Workbook

Sheet Dashboard
B1: IFA CONTACT DASHBOARD
B2: Live overview of every contact in the database. Add or edit a contact on the RawData tab and every number here moves with it.
B3: ="Contacts in database: "&TEXT(COUNTA(c_Name),"#,##0")&" | Refreshed: "&TEXT(TODAY(),"d mmm yyyy") -> Contacts in database: 369 | Refreshed: 7 Aug 2026
B5: TOTAL CONTACTS | E5: FIRMS COVERED | H5: CONTACTS MET | K5: MEETING COVERAGE
B6: =COUNTA(c_Name) -> 369 | E6: =SUMPRODUCT((c_Firm<>"")/COUNTIF(c_Firm,c_Firm&"")) -> 22 | H6: =COUNTIF(c_Met,"Yes") -> 51 | K6: =IFERROR(COUNTIF(c_Met,"Yes")/COUNTA(c_Name),0) -> 0.13821138
B8: TOTAL MEETINGS | E8: INVITED TO AN EVENT | H8: ATTENDED AN EVENT | K8: EVENT ATTENDANCE RATE
B9: =SUM(c_Mtgs) -> 51 | E9: =COUNTIF(c_EvtInv,">0") -> 128 | H9: =COUNTIF(c_EvtAtt,">0") -> 77 | K9: =IFERROR(COUNTIF(c_EvtAtt,">0")/COUNTIF(c_EvtInv,">0"),0) -> 0.6015625
B11: MET IN LAST 90 DAYS | E11: NEVER CONTACTED | H11: INVESTORS | K11: ILP AUM TRACKED (S$M)
B12: =COUNTIFS(c_Date,">="&TODAY()-90) -> 0 | E12: =COUNTIF(c_Engage,"Not yet contacted") -> 91 | H12: =COUNTIF(c_Invested,"Yes") -> 7 | K12: =SUM(c_AUM)/1000000 -> 922
B14: WHERE THEY COME FROM — CONTACTS BY FIRM | F14: sorted by size; % Met = share of that firm you have already met
B15: Firm | C15: Contacts | D15: % of DB | E15: Met | F15: % Met | G15: Meetings | H15: Invited to events | I15: Attended events | J15: Investors | K15: ILP AUM (S$m)
B16: PIAS | C16: =COUNTIF(c_Firm,$B16) -> 117 | D16: =IFERROR($C16/COUNTA(c_Name),0) -> 0.31707317 | E16: =COUNTIFS(c_Firm,$B16,c_Met,"Yes") -> 7 | F16: =IFERROR($E16/$C16,0) -> 0.05982906 | G16: =SUMIF(c_Firm,$B16,c_Mtgs) -> 7 | H16: =COUNTIFS(c_Firm,$B16,c_EvtInv,">0") -> 8 | I16: =COUNTIFS(c_Firm,$B16,c_EvtAtt,">0") -> 5 | J16: =COUNTIFS(c_Firm,$B16,c_Invested,"Yes") -> 1 | K16: =SUMIF(c_Firm,$B16,c_AUM)/1000000 -> 125
B17: Finexis Advisory | C17: =COUNTIF(c_Firm,$B17) -> 50 | D17: =IFERROR($C17/COUNTA(c_Name),0) -> 0.13550136 | E17: =COUNTIFS(c_Firm,$B17,c_Met,"Yes") -> 7 | F17: =IFERROR($E17/$C17,0) -> 0.14 | G17: =SUMIF(c_Firm,$B17,c_Mtgs) -> 7 | H17: =COUNTIFS(c_Firm,$B17,c_EvtInv,">0") -> 11 | I17: =COUNTIFS(c_Firm,$B17,c_EvtAtt,">0") -> 9 | J17: =COUNTIFS(c_Firm,$B17,c_Invested,"Yes") -> 2 | K17: =SUMIF(c_Firm,$B17,c_AUM)/1000000 -> 247
B18: Manulife FA | C18: =COUNTIF(c_Firm,$B18) -> 38 | D18: =IFERROR($C18/COUNTA(c_Name),0) -> 0.10298103 | E18: =COUNTIFS(c_Firm,$B18,c_Met,"Yes") -> 0 | F18: =IFERROR($E18/$C18,0) -> 0 | G18: =SUMIF(c_Firm,$B18,c_Mtgs) -> 0 | H18: =COUNTIFS(c_Firm,$B18,c_EvtInv,">0") -> 0 | I18: =COUNTIFS(c_Firm,$B18,c_EvtAtt,">0") -> 0 | J18: =COUNTIFS(c_Firm,$B18,c_Invested,"Yes") -> 0 | K18: =SUMIF(c_Firm,$B18,c_AUM)/1000000 -> 0
B19: Synergy | C19: =COUNTIF(c_Firm,$B19) -> 34 | D19: =IFERROR($C19/COUNTA(c_Name),0) -> 0.092140921 | E19: =COUNTIFS(c_Firm,$B19,c_Met,"Yes") -> 7 | F19: =IFERROR($E19/$C19,0) -> 0.20588235 | G19: =SUMIF(c_Firm,$B19,c_Mtgs) -> 7 | H19: =COUNTIFS(c_Firm,$B19,c_EvtInv,">0") -> 30 | I19: =COUNTIFS(c_Firm,$B19,c_EvtAtt,">0") -> 15 | J19: =COUNTIFS(c_Firm,$B19,c_Invested,"Yes") -> 2 | K19: =SUMIF(c_Firm,$B19,c_AUM)/1000000 -> 142
B20: iFast | C20: =COUNTIF(c_Firm,$B20) -> 27 | D20: =IFERROR($C20/COUNTA(c_Name),0) -> 0.073170732 | E20: =COUNTIFS(c_Firm,$B20,c_Met,"Yes") -> 2 | F20: =IFERROR($E20/$C20,0) -> 0.074074074 | G20: =SUMIF(c_Firm,$B20,c_Mtgs) -> 2 | H20: =COUNTIFS(c_Firm,$B20,c_EvtInv,">0") -> 8 | I20: =COUNTIFS(c_Firm,$B20,c_EvtAtt,">0") -> 7 | J20: =COUNTIFS(c_Firm,$B20,c_Invested,"Yes") -> 1 | K20: =SUMIF(c_Firm,$B20,c_AUM)/1000000 -> 148
B21: Financial Alliance | C21: =COUNTIF(c_Firm,$B21) -> 23 | D21: =IFERROR($C21/COUNTA(c_Name),0) -> 0.062330623 | E21: =COUNTIFS(c_Firm,$B21,c_Met,"Yes") -> 9 | F21: =IFERROR($E21/$C21,0) -> 0.39130435 | G21: =SUMIF(c_Firm,$B21,c_Mtgs) -> 9 | H21: =COUNTIFS(c_Firm,$B21,c_EvtInv,">0") -> 23 | I21: =COUNTIFS(c_Firm,$B21,c_EvtAtt,">0") -> 15 | J21: =COUNTIFS(c_Firm,$B21,c_Invested,"Yes") -> 1 | K21: =SUMIF(c_Firm,$B21,c_AUM)/1000000 -> 75
B22: Phillip Capital | C22: =COUNTIF(c_Firm,$B22) -> 23 | D22: =IFERROR($C22/COUNTA(c_Name),0) -> 0.062330623 | E22: =COUNTIFS(c_Firm,$B22,c_Met,"Yes") -> 7 | F22: =IFERROR($E22/$C22,0) -> 0.30434783 | G22: =SUMIF(c_Firm,$B22,c_Mtgs) -> 7 | H22: =COUNTIFS(c_Firm,$B22,c_EvtInv,">0") -> 18 | I22: =COUNTIFS(c_Firm,$B22,c_EvtAtt,">0") -> 9 | J22: =COUNTIFS(c_Firm,$B22,c_Invested,"Yes") -> 0 | K22: =SUMIF(c_Firm,$B22,c_AUM)/1000000 -> 102
B23: Singlife | C23: =COUNTIF(c_Firm,$B23) -> 15 | D23: =IFERROR($C23/COUNTA(c_Name),0) -> 0.040650407 | E23: =COUNTIFS(c_Firm,$B23,c_Met,"Yes") -> 3 | F23: =IFERROR($E23/$C23,0) -> 0.2 | G23: =SUMIF(c_Firm,$B23,c_Mtgs) -> 3 | H23: =COUNTIFS(c_Firm,$B23,c_EvtInv,">0") -> 5 | I23: =COUNTIFS(c_Firm,$B23,c_EvtAtt,">0") -> 3 | J23: =COUNTIFS(c_Firm,$B23,c_Invested,"Yes") -> 0 | K23: =SUMIF(c_Firm,$B23,c_AUM)/1000000 -> 0
B24: Infinity FA | C24: =COUNTIF(c_Firm,$B24) -> 12 | D24: =IFERROR($C24/COUNTA(c_Name),0) -> 0.032520325 | E24: =COUNTIFS(c_Firm,$B24,c_Met,"Yes") -> 2 | F24: =IFERROR($E24/$C24,0) -> 0.16666667 | G24: =SUMIF(c_Firm,$B24,c_Mtgs) -> 2 | H24: =COUNTIFS(c_Firm,$B24,c_EvtInv,">0") -> 12 | I24: =COUNTIFS(c_Firm,$B24,c_EvtAtt,">0") -> 9 | J24: =COUNTIFS(c_Firm,$B24,c_Invested,"Yes") -> 0 | K24: =SUMIF(c_Firm,$B24,c_AUM)/1000000 -> 67
B25: Income Advisory | C25: =COUNTIF(c_Firm,$B25) -> 11 | D25: =IFERROR($C25/COUNTA(c_Name),0) -> 0.029810298 | E25: =COUNTIFS(c_Firm,$B25,c_Met,"Yes") -> 0 | F25: =IFERROR($E25/$C25,0) -> 0 | G25: =SUMIF(c_Firm,$B25,c_Mtgs) -> 0 | H25: =COUNTIFS(c_Firm,$B25,c_EvtInv,">0") -> 0 | I25: =COUNTIFS(c_Firm,$B25,c_EvtAtt,">0") -> 0 | J25: =COUNTIFS(c_Firm,$B25,c_Invested,"Yes") -> 0 | K25: =SUMIF(c_Firm,$B25,c_AUM)/1000000 -> 0
B26: PromiseLand | C26: =COUNTIF(c_Firm,$B26) -> 5 | D26: =IFERROR($C26/COUNTA(c_Name),0) -> 0.013550136 | E26: =COUNTIFS(c_Firm,$B26,c_Met,"Yes") -> 1 | F26: =IFERROR($E26/$C26,0) -> 0.2 | G26: =SUMIF(c_Firm,$B26,c_Mtgs) -> 1 | H26: =COUNTIFS(c_Firm,$B26,c_EvtInv,">0") -> 1 | I26: =COUNTIFS(c_Firm,$B26,c_EvtAtt,">0") -> 0 | J26: =COUNTIFS(c_Firm,$B26,c_Invested,"Yes") -> 0 | K26: =SUMIF(c_Firm,$B26,c_AUM)/1000000 -> 5
B27: Alpha Wealth | C27: =COUNTIF(c_Firm,$B27) -> 3 | D27: =IFERROR($C27/COUNTA(c_Name),0) -> 0.0081300813 | E27: =COUNTIFS(c_Firm,$B27,c_Met,"Yes") -> 0 | F27: =IFERROR($E27/$C27,0) -> 0 | G27: =SUMIF(c_Firm,$B27,c_Mtgs) -> 0 | H27: =COUNTIFS(c_Firm,$B27,c_EvtInv,">0") -> 3 | I27: =COUNTIFS(c_Firm,$B27,c_EvtAtt,">0") -> 2 | J27: =COUNTIFS(c_Firm,$B27,c_Invested,"Yes") -> 0 | K27: =SUMIF(c_Firm,$B27,c_AUM)/1000000 -> 0
... B37: SG Alliance | C37: =COUNTIF(c_Firm,$B37) -> 1 | D37: =IFERROR($C37/COUNTA(c_Name),0) -> 0.0027100271 | E37: =COUNTIFS(c_Firm,$B37,c_Met,"Yes") -> 0 | F37: =IFERROR($E37/$C37,0) -> 0 | G37: =SUMIF(c_Firm,$B37,c_Mtgs) -> 0 | H37: =COUNTIFS(c_Firm,$B37,c_EvtInv,">0") -> 1 | I37: =COUNTIFS(c_Firm,$B37,c_EvtAtt,">0") -> 1 | J37: =COUNTIFS(c_Firm,$B37,c_Invested,"Yes") -> 0 | K37: =SUMIF(c_Firm,$B37,c_AUM)/1000000 -> 0
B38: TOTAL | C38: =SUM(C16:C37) -> 369 | D38: =IFERROR($C38/COUNTA(c_Name),0) -> 1 | E38: =SUM(E16:E37) -> 51 | F38: =IFERROR($E38/$C38,0) -> 0.13821138 | G38: =SUM(G16:G37) -> 51 | H38: =SUM(H16:H37) -> 128 | I38: =SUM(I16:I37) -> 77 | J38: =SUM(J16:J37) -> 7 | K38: =SUM(K16:K37) -> 922
B39: Contacts whose firm is missing from the Setup list (should be 0): | F39: =COUNTA(c_Name)-$C$38 -> 0
B41: WHICH EVENT THEY CAME TO | F41: status per contact lives in RawData columns N–R
B42: Event | C42: Date | D42: Invited | E42: Attended | F42: No show | G42: Declined | H42: No reply | I42: Pending | J42: Attendance rate
B43: =IF(Setup!$C$15="","(free slot 1)",Setup!$C$15) -> H2O AM IFA Symposium (October 2025) | C43: =IF(Setup!$E$15="","",Setup!$E$15) -> 45931 | D43: =COUNTA(c_E1)-COUNTIF(c_E1,"Not Invited") -> 75 | E43: =COUNTIF(c_E1,"Attended") -> 34 | F43: =COUNTIF(c_E1,"No Show") -> 0 | G43: =COUNTIF(c_E1,"Declined") -> 24 | H43: =COUNTIF(c_E1,"No Reply") -> 17 | I43: =COUNTIF(c_E1,"Invited")+COUNTIF(c_E1,"Accepted") -> 0 | J43: =IFERROR($E43/$D43,"") -> 0.45333333
B44: =IF(Setup!$C$16="","(free slot 2)",Setup!$C$16) -> 2nd Edition H2O AM IFA Symposium (May 2026) | C44: =IF(Setup!$E$16="","",Setup!$E$16) -> 46143 | D44: =COUNTA(c_E2)-COUNTIF(c_E2,"Not Invited") -> 123 | E44: =COUNTIF(c_E2,"Attended") -> 55 | F44: =COUNTIF(c_E2,"No Show") -> 11 | G44: =COUNTIF(c_E2,"Declined") -> 32 | H44: =COUNTIF(c_E2,"No Reply") -> 24 | I44: =COUNTIF(c_E2,"Invited")+COUNTIF(c_E2,"Accepted") -> 1 | J44: =IFERROR($E44/$D44,"") -> 0.44715447
B45: =IF(Setup!$C$17="","(free slot 3)",Setup!$C$17) -> Macro Lunch series | C45: =IF(Setup!$E$17="","",Setup!$E$17) -> 46226 | D45: =COUNTA(c_E3)-COUNTIF(c_E3,"Not Invited") -> 3 | E45: =COUNTIF(c_E3,"Attended") -> 0 | F45: =COUNTIF(c_E3,"No Show") -> 0 | G45: =COUNTIF(c_E3,"Declined") -> 0 | H45: =COUNTIF(c_E3,"No Reply") -> 0 | I45: =COUNTIF(c_E3,"Invited")+COUNTIF(c_E3,"Accepted") -> 3 | J45: =IFERROR($E45/$D45,"") -> 0
B46: =IF(Setup!$C$18="","(free slot 4)",Setup!$C$18) -> (free slot 4) | C46: =IF(Setup!$E$18="","",Setup!$E$18) | D46: =COUNTA(c_E4)-COUNTIF(c_E4,"Not Invited") -> 0 | E46: =COUNTIF(c_E4,"Attended") -> 0 | F46: =COUNTIF(c_E4,"No Show") -> 0 | G46: =COUNTIF(c_E4,"Declined") -> 0 | H46: =COUNTIF(c_E4,"No Reply") -> 0 | I46: =COUNTIF(c_E4,"Invited")+COUNTIF(c_E4,"Accepted") -> 0 | J46: =IFERROR($E46/$D46,"")
B47: =IF(Setup!$C$19="","(free slot 5)",Setup!$C$19) -> (free slot 5) | C47: =IF(Setup!$E$19="","",Setup!$E$19) | D47: =COUNTA(c_E5)-COUNTIF(c_E5,"Not Invited") -> 0 | E47: =COUNTIF(c_E5,"Attended") -> 0 | F47: =COUNTIF(c_E5,"No Show") -> 0 | G47: =COUNTIF(c_E5,"Declined") -> 0 | H47: =COUNTIF(c_E5,"No Reply") -> 0 | I47: =COUNTIF(c_E5,"Invited")+COUNTIF(c_E5,"Accepted") -> 0 | J47: =IFERROR($E47/$D47,"")
B49: HOW WARM THEY ARE | F49: WHICH LIST THEY CAME FROM
B50: Stage | C50: Contacts | D50: % of DB | F50: Source list | G50: Contacts | H50: % of DB
B51: Event attendee | C51: =COUNTIF(c_Engage,$B51) -> 77 | D51: =IFERROR($C51/COUNTA(c_Name),0) -> 0.20867209 | F51: Meeting List | G51: =COUNTIF(c_Source,"*"&$F51&"*") -> 129 | H51: =IFERROR($G51/COUNTA(c_Name),0) -> 0.3495935
B52: Met (no event) | C52: =COUNTIF(c_Engage,$B52) -> 28 | D52: =IFERROR($C52/COUNTA(c_Name),0) -> 0.075880759 | F52: Branch Directors | G52: =COUNTIF(c_Source,"*"&$F52&"*") -> 173 | H52: =IFERROR($G52/COUNTA(c_Name),0) -> 0.46883469
B53: Invited only | C53: =COUNTIF(c_Engage,$B53) -> 24 | D53: =IFERROR($C53/COUNTA(c_Name),0) -> 0.06504065 | F53: Mass Email PIAS | G53: =COUNTIF(c_Source,"*"&$F53&"*") -> 85 | H53: =IFERROR($G53/COUNTA(c_Name),0) -> 0.2303523
B54: Contacted only | C54: =COUNTIF(c_Engage,$B54) -> 149 | D54: =IFERROR($C54/COUNTA(c_Name),0) -> 0.40379404 | F54: ILP Data | G54: =COUNTIF(c_Source,"*"&$F54&"*") -> 73 | H54: =IFERROR($G54/COUNTA(c_Name),0) -> 0.19783198
B55: Not yet contacted | C55: =COUNTIF(c_Engage,$B55) -> 91 | D55: =IFERROR($C55/COUNTA(c_Name),0) -> 0.24661247
...

Sheet Meeting Stats
B1: MEETING STATISTICS
B2: Built from the Met? / Last Meeting / # Meetings columns of RawData. The source file records one LAST MEETING date per contact, so the monthly split below shows each contact once, in the month you last saw them.
B5: TOTAL MEETINGS | E5: CONTACTS MET | H5: DATABASE MET | K5: MEETINGS PER CONTACT
B6: =SUM(c_Mtgs) -> 51 | E6: =COUNTIF(c_Met,"Yes") -> 51 | H6: =IFERROR(COUNTIF(c_Met,"Yes")/COUNTA(c_Name),0) -> 0.13821138 | K6: =IFERROR(SUM(c_Mtgs)/COUNTIF(c_Met,"Yes"),0) -> 1
B8: FIRST MEETING | E8: MOST RECENT MEETING | H8: MET IN LAST 30 DAYS | K8: OVERDUE (>120 DAYS)
B9: =IFERROR(MIN(c_Date),"") -> 45412 | E9: =IFERROR(MAX(c_Date),"") -> 46134 | H9: =COUNTIFS(c_Date,">="&TODAY()-30) -> 0 | K9: =COUNTIF(c_Days,">120") -> 49
B11: MEETING ACTIVITY BY MONTH | F11: rolling 18 months
B12: Month | C12: Contacts met | D12: Cumulative (window)
B13: =EOMONTH(TODAY(),-18)+1 -> 45717 | C13: =COUNTIFS(c_Date,">="&$B13,c_Date,"<="&EOMONTH($B13,0)) -> 1 | D13: =$C13 -> 1
B14: =EOMONTH($B13,0)+1 -> 45748 | C14: =COUNTIFS(c_Date,">="&$B14,c_Date,"<="&EOMONTH($B14,0)) -> 0 | D14: =$D13+$C14 -> 1
B15: =EOMONTH($B14,0)+1 -> 45778 | C15: =COUNTIFS(c_Date,">="&$B15,c_Date,"<="&EOMONTH($B15,0)) -> 0 | D15: =$D14+$C15 -> 1
B16: =EOMONTH($B15,0)+1 -> 45809 | C16: =COUNTIFS(c_Date,">="&$B16,c_Date,"<="&EOMONTH($B16,0)) -> 4 | D16: =$D15+$C16 -> 5
B17: =EOMONTH($B16,0)+1 -> 45839 | C17: =COUNTIFS(c_Date,">="&$B17,c_Date,"<="&EOMONTH($B17,0)) -> 0 | D17: =$D16+$C17 -> 5
B18: =EOMONTH($B17,0)+1 -> 45870 | C18: =COUNTIFS(c_Date,">="&$B18,c_Date,"<="&EOMONTH($B18,0)) -> 2 | D18: =$D17+$C18 -> 7
B19: =EOMONTH($B18,0)+1 -> 45901 | C19: =COUNTIFS(c_Date,">="&$B19,c_Date,"<="&EOMONTH($B19,0)) -> 12 | D19: =$D18+$C19 -> 19
B20: =EOMONTH($B19,0)+1 -> 45931 | C20: =COUNTIFS(c_Date,">="&$B20,c_Date,"<="&EOMONTH($B20,0)) -> 7 | D20: =$D19+$C20 -> 26
B21: =EOMONTH($B20,0)+1 -> 45962 | C21: =COUNTIFS(c_Date,">="&$B21,c_Date,"<="&EOMONTH($B21,0)) -> 5 | D21: =$D20+$C21 -> 31
B22: =EOMONTH($B21,0)+1 -> 45992 | C22: =COUNTIFS(c_Date,">="&$B22,c_Date,"<="&EOMONTH($B22,0)) -> 4 | D22: =$D21+$C22 -> 35
B23: =EOMONTH($B22,0)+1 -> 46023 | C23: =COUNTIFS(c_Date,">="&$B23,c_Date,"<="&EOMONTH($B23,0)) -> 4 | D23: =$D22+$C23 -> 39
B24: =EOMONTH($B23,0)+1 -> 46054 | C24: =COUNTIFS(c_Date,">="&$B24,c_Date,"<="&EOMONTH($B24,0)) -> 2 | D24: =$D23+$C24 -> 41
B25: =EOMONTH($B24,0)+1 -> 46082 | C25: =COUNTIFS(c_Date,">="&$B25,c_Date,"<="&EOMONTH($B25,0)) -> 4 | D25: =$D24+$C25 -> 45
... B30: =EOMONTH($B29,0)+1 -> 46235 | C30: =COUNTIFS(c_Date,">="&$B30,c_Date,"<="&EOMONTH($B30,0)) -> 0 | D30: =$D29+$C30 -> 47
B32: MEETING COVERAGE BY FIRM | F32: which firms you have actually worked
B33: Firm | C33: Contacts | D33: Met | E33: Coverage | F33: Meetings | G33: Last meeting | H33: Days since | I33: Attended an event
B34: Financial Alliance | C34: =COUNTIF(c_Firm,$B34) -> 23 | D34: =COUNTIFS(c_Firm,$B34,c_Met,"Yes") -> 9 | E34: =IFERROR($D34/$C34,0) -> 0.39130435 | F34: =SUMIF(c_Firm,$B34,c_Mtgs) -> 9 | G34: =IF(_xlfn.MAXIFS(c_Date,c_Firm,$B34)=0,"",_xlfn.MAXIFS(c_Date,c_Firm,$B34)) -> 46043 | H34: =IF($G34="","",TODAY()-$G34) -> 198 | I34: =COUNTIFS(c_Firm,$B34,c_EvtAtt,">0") -> 15
B35: Finexis Advisory | C35: =COUNTIF(c_Firm,$B35) -> 50 | D35: =COUNTIFS(c_Firm,$B35,c_Met,"Yes") -> 7 | E35: =IFERROR($D35/$C35,0) -> 0.14 | F35: =SUMIF(c_Firm,$B35,c_Mtgs) -> 7 | G35: =IF(_xlfn.MAXIFS(c_Date,c_Firm,$B35)=0,"",_xlfn.MAXIFS(c_Date,c_Firm,$B35)) -> 46007 | H35: =IF($G35="","",TODAY()-$G35) -> 234 | I35: =COUNTIFS(c_Firm,$B35,c_EvtAtt,">0") -> 9
B36: PIAS | C36: =COUNTIF(c_Firm,$B36) -> 117 | D36: =COUNTIFS(c_Firm,$B36,c_Met,"Yes") -> 7 | E36: =IFERROR($D36/$C36,0) -> 0.05982906 | F36: =SUMIF(c_Firm,$B36,c_Mtgs) -> 7 | G36: =IF(_xlfn.MAXIFS(c_Date,c_Firm,$B36)=0,"",_xlfn.MAXIFS(c_Date,c_Firm,$B36)) -> 46090 | H36: =IF($G36="","",TODAY()-$G36) -> 151 | I36: =COUNTIFS(c_Firm,$B36,c_EvtAtt,">0") -> 5
B37: Phillip Capital | C37: =COUNTIF(c_Firm,$B37) -> 23 | D37: =COUNTIFS(c_Firm,$B37,c_Met,"Yes") -> 7 | E37: =IFERROR($D37/$C37,0) -> 0.30434783 | F37: =SUMIF(c_Firm,$B37,c_Mtgs) -> 7 | G37: =IF(_xlfn.MAXIFS(c_Date,c_Firm,$B37)=0,"",_xlfn.MAXIFS(c_Date,c_Firm,$B37)) -> 46045 | H37: =IF($G37="","",TODAY()-$G37) -> 196 | I37: =COUNTIFS(c_Firm,$B37,c_EvtAtt,">0") -> 9
B38: Synergy | C38: =COUNTIF(c_Firm,$B38) -> 34 | D38: =COUNTIFS(c_Firm,$B38,c_Met,"Yes") -> 7 | E38: =IFERROR($D38/$C38,0) -> 0.20588235 | F38: =SUMIF(c_Firm,$B38,c_Mtgs) -> 7 | G38: =IF(_xlfn.MAXIFS(c_Date,c_Firm,$B38)=0,"",_xlfn.MAXIFS(c_Date,c_Firm,$B38)) -> 46091 | H38: =IF($G38="","",TODAY()-$G38) -> 150 | I38: =COUNTIFS(c_Firm,$B38,c_EvtAtt,">0") -> 15
B39: Singlife | C39: =COUNTIF(c_Firm,$B39) -> 15 | D39: =COUNTIFS(c_Firm,$B39,c_Met,"Yes") -> 3 | E39: =IFERROR($D39/$C39,0) -> 0.2 | F39: =SUMIF(c_Firm,$B39,c_Mtgs) -> 3 | G39: =IF(_xlfn.MAXIFS(c_Date,c_Firm,$B39)=0,"",_xlfn.MAXIFS(c_Date,c_Firm,$B39)) -> 45897 | H39: =IF($G39="","",TODAY()-$G39) -> 344 | I39: =COUNTIFS(c_Firm,$B39,c_EvtAtt,">0") -> 3
B40: GYC Financial Advisory | C40: =COUNTIF(c_Firm,$B40) -> 2 | D40: =COUNTIFS(c_Firm,$B40,c_Met,"Yes") -> 2 | E40: =IFERROR($D40/$C40,0) -> 1 | F40: =SUMIF(c_Firm,$B40,c_Mtgs) -> 2 | G40: =IF(_xlfn.MAXIFS(c_Date,c_Firm,$B40)=0,"",_xlfn.MAXIFS(c_Date,c_Firm,$B40)) -> 45412 | H40: =IF($G40="","",TODAY()-$G40) -> 829 | I40: =COUNTIFS(c_Firm,$B40,c_EvtAtt,">0") -> 0
B41: Infinity FA | C41: =COUNTIF(c_Firm,$B41) -> 12 | D41: =COUNTIFS(c_Firm,$B41,c_Met,"Yes") -> 2 | E41: =IFERROR($D41/$C41,0) -> 0.16666667 | F41: =SUMIF(c_Firm,$B41,c_Mtgs) -> 2 | G41: =IF(_xlfn.MAXIFS(c_Date,c_Firm,$B41)=0,"",_xlfn.MAXIFS(c_Date,c_Firm,$B41)) -> 46056 | H41: =IF($G41="","",TODAY()-$G41) -> 185 | I41: =COUNTIFS(c_Firm,$B41,c_EvtAtt,">0") -> 9
B42: iFast | C42: =COUNTIF(c_Firm,$B42) -> 27 | D42: =COUNTIFS(c_Firm,$B42,c_Met,"Yes") -> 2 | E42: =IFERROR($D42/$C42,0) -> 0.074074074 | F42: =SUMIF(c_Firm,$B42,c_Mtgs) -> 2 | G42: =IF(_xlfn.MAXIFS(c_Date,c_Firm,$B42)=0,"",_xlfn.MAXIFS(c_Date,c_Firm,$B42)) -> 46132 | H42: =IF($G42="","",TODAY()-$G42) -> 109 | I42: =COUNTIFS(c_Firm,$B42,c_EvtAtt,">0") -> 7
B43: Great Eastern Life | C43: =COUNTIF(c_Firm,$B43) -> 1 | D43: =COUNTIFS(c_Firm,$B43,c_Met,"Yes") -> 1 | E43: =IFERROR($D43/$C43,0) -> 1 | F43: =SUMIF(c_Firm,$B43,c_Mtgs) -> 1 | G43: =IF(_xlfn.MAXIFS(c_Date,c_Firm,$B43)=0,"",_xlfn.MAXIFS(c_Date,c_Firm,$B43)) -> 45989 | H43: =IF($G43="","",TODAY()-$G43) -> 252 | I43: =COUNTIFS(c_Firm,$B43,c_EvtAtt,">0") -> 1
B44: HSBC Life | C44: =COUNTIF(c_Firm,$B44) -> 1 | D44: =COUNTIFS(c_Firm,$B44,c_Met,"Yes") -> 1 | E44: =IFERROR($D44/$C44,0) -> 1 | F44: =SUMIF(c_Firm,$B44,c_Mtgs) -> 1 | G44: =IF(_xlfn.MAXIFS(c_Date,c_Firm,$B44)=0,"",_xlfn.MAXIFS(c_Date,c_Firm,$B44)) -> 46062 | H44: =IF($G44="","",TODAY()-$G44) -> 179 | I44: =COUNTIFS(c_Firm,$B44,c_EvtAtt,">0") -> 0
B45: IPP FA | C45: =COUNTIF(c_Firm,$B45) -> 1 | D45: =COUNTIFS(c_Firm,$B45,c_Met,"Yes") -> 1 | E45: =IFERROR($D45/$C45,0) -> 1 | F45: =SUMIF(c_Firm,$B45,c_Mtgs) -> 1 | G45: =IF(_xlfn.MAXIFS(c_Date,c_Firm,$B45)=0,"",_xlfn.MAXIFS(c_Date,c_Firm,$B45)) -> 46084 | H45: =IF($G45="","",TODAY()-$G45) -> 157 | I45: =COUNTIFS(c_Firm,$B45,c_EvtAtt,">0") -> 0
... B55: SG Alliance | C55: =COUNTIF(c_Firm,$B55) -> 1 | D55: =COUNTIFS(c_Firm,$B55,c_Met,"Yes") -> 0 | E55: =IFERROR($D55/$C55,0) -> 0 | F55: =SUMIF(c_Firm,$B55,c_Mtgs) -> 0 | G55: =IF(_xlfn.MAXIFS(c_Date,c_Firm,$B55)=0,"",_xlfn.MAXIFS(c_Date,c_Firm,$B55)) | H55: =IF($G55="","",TODAY()-$G55) | I55: =COUNTIFS(c_Firm,$B55,c_EvtAtt,">0") -> 1
B57: OLDEST RELATIONSHIPS — FOLLOW UP FIRST | F57: the contacts you have met whose last meeting is furthest in the past
B58: Name | C58: Firm | D58: Last meeting | E58: Days since | F58: Events attended | G58: Invested? | H58: Email
A59: =IFERROR(MATCH(1,c_FUp,0),"") -> 79 | B59: =IF($A59="","",INDEX(c_Name,$A59)) -> Bruce Tan | C59: =IF($A59="","",INDEX(c_Firm,$A59)) -> GYC Financial Advisory | D59: =IF($A59="","",INDEX(c_Date,$A59)) -> 45412 | E59: =IF($A59="","",INDEX(c_Days,$A59)) -> 829 | F59: =IF($A59="","",INDEX(c_EvtNames,$A59)&"") | G59: =IF($A59="","",INDEX(c_Invested,$A59)) -> TBC | H59: =IF($A59="","",INDEX(c_Email,$A59)&"") -> brucetan@gyc.com.sg
...

Sheet Contacts
B1: CONTACT DIRECTORY
B2: Every contact, sorted by firm then name. Change any of the yellow filter boxes below and the list rebuilds instantly.
B3: Firm: | C3: (All) | D3: Met?: | E3: (All) | F3: Attended: | G3: (All) | H3: Warmth: | I3: (All) | J3: Search: | M3: =TEXT(COUNTIF(c_Pass,1),"#,##0")&" of "&TEXT(COUNTA(c_Name),"#,##0")&" contacts shown" -> 369 of 369 contacts shown
B5: Name | C5: Firm | D5: Type | E5: Email | F5: Met? | G5: Last meeting | H5: Days since | I5: # Mtgs | J5: Events attended | K5: Invested? | L5: AUM (S$) | M5: Source | N5: Notes
A6: =IFERROR(MATCH(ROW()-5,c_Seq,0),"") -> 1 | B6: =IF($A6="","",INDEX(c_Name,$A6)&"") -> Ang hui | C6: =IF($A6="","",INDEX(c_Firm,$A6)&"") -> Alpha Wealth | D6: =IF($A6="","",INDEX(c_Type,$A6)&"") -> Adviser | E6: =IF($A6="","",INDEX(c_Email,$A6)&"") -> anghuichin@awfa.com.sg | F6: =IF($A6="","",INDEX(c_Met,$A6)&"") -> No | G6: =IF($A6="","",IF(INDEX(c_Date,$A6)="","",INDEX(c_Date,$A6))) | H6: =IF($A6="","",IF(INDEX(c_Days,$A6)="","",INDEX(c_Days,$A6))) | I6: =IF($A6="","",IF(INDEX(c_Mtgs,$A6)="","",INDEX(c_Mtgs,$A6))) -> 0 | J6: =IF($A6="","",INDEX(c_EvtNames,$A6)&"") | K6: =IF($A6="","",INDEX(c_Invested,$A6)&"") -> No | L6: =IF($A6="","",IF(INDEX(c_AUM,$A6)="","",INDEX(c_AUM,$A6))) | M6: =IF($A6="","",INDEX(c_Source,$A6)&"") -> Meeting List | N6: =IF($A6="","",INDEX(c_Notes,$A6)&"")
A7: =IFERROR(MATCH(ROW()-5,c_Seq,0),"") -> 2 | B7: =IF($A7="","",INDEX(c_Name,$A7)&"") -> Jason Yin | C7: =IF($A7="","",INDEX(c_Firm,$A7)&"") -> Alpha Wealth | D7: =IF($A7="","",INDEX(c_Type,$A7)&"") -> Adviser | E7: =IF($A7="","",INDEX(c_Email,$A7)&"") -> jasonyin@awfa.com.sg | F7: =IF($A7="","",INDEX(c_Met,$A7)&"") -> No | G7: =IF($A7="","",IF(INDEX(c_Date,$A7)="","",INDEX(c_Date,$A7))) | H7: =IF($A7="","",IF(INDEX(c_Days,$A7)="","",INDEX(c_Days,$A7))) | I7: =IF($A7="","",IF(INDEX(c_Mtgs,$A7)="","",INDEX(c_Mtgs,$A7))) -> 0 | J7: =IF($A7="","",INDEX(c_EvtNames,$A7)&"") -> May-26 Symposium | K7: =IF($A7="","",INDEX(c_Invested,$A7)&"") -> No | L7: =IF($A7="","",IF(INDEX(c_AUM,$A7)="","",INDEX(c_AUM,$A7))) | M7: =IF($A7="","",INDEX(c_Source,$A7)&"") -> Meeting List | N7: =IF($A7="","",INDEX(c_Notes,$A7)&"")
A8: =IFERROR(MATCH(ROW()-5,c_Seq,0),"") -> 3 | B8: =IF($A8="","",INDEX(c_Name,$A8)&"") -> Lee Jia Hao | C8: =IF($A8="","",INDEX(c_Firm,$A8)&"") -> Alpha Wealth | D8: =IF($A8="","",INDEX(c_Type,$A8)&"") -> Adviser | E8: =IF($A8="","",INDEX(c_Email,$A8)&"") -> leejiahao@awfa.com.sg | F8: =IF($A8="","",INDEX(c_Met,$A8)&"") -> No | G8: =IF($A8="","",IF(INDEX(c_Date,$A8)="","",INDEX(c_Date,$A8))) | H8: =IF($A8="","",IF(INDEX(c_Days,$A8)="","",INDEX(c_Days,$A8))) | I8: =IF($A8="","",IF(INDEX(c_Mtgs,$A8)="","",INDEX(c_Mtgs,$A8))) -> 0 | J8: =IF($A8="","",INDEX(c_EvtNames,$A8)&"") -> May-26 Symposium | K8: =IF($A8="","",INDEX(c_Invested,$A8)&"") -> No | L8: =IF($A8="","",IF(INDEX(c_AUM,$A8)="","",INDEX(c_AUM,$A8))) | M8: =IF($A8="","",INDEX(c_Source,$A8)&"") -> Meeting List | N8: =IF($A8="","",INDEX(c_Notes,$A8)&"")
A9: =IFERROR(MATCH(ROW()-5,c_Seq,0),"") -> 4 | B9: =IF($A9="","",INDEX(c_Name,$A9)&"") -> Alvin Low | C9: =IF($A9="","",INDEX(c_Firm,$A9)&"") -> Financial Alliance | D9: =IF($A9="","",INDEX(c_Type,$A9)&"") -> Adviser | E9: =IF($A9="","",INDEX(c_Email,$A9)&"") -> alvinlow@fapl.sg | F9: =IF($A9="","",INDEX(c_Met,$A9)&"") -> Yes | G9: =IF($A9="","",IF(INDEX(c_Date,$A9)="","",INDEX(c_Date,$A9))) -> 45918 | H9: =IF($A9="","",IF(INDEX(c_Days,$A9)="","",INDEX(c_Days,$A9))) -> 323 | I9: =IF($A9="","",IF(INDEX(c_Mtgs,$A9)="","",INDEX(c_Mtgs,$A9))) -> 1 | J9: =IF($A9="","",INDEX(c_EvtNames,$A9)&"") | K9: =IF($A9="","",INDEX(c_Invested,$A9)&"") -> No | L9: =IF($A9="","",IF(INDEX(c_AUM,$A9)="","",INDEX(c_AUM,$A9))) -> 5000000 | M9: =IF($A9="","",INDEX(c_Source,$A9)&"") -> Meeting List + ILP Data | N9: =IF($A9="","",INDEX(c_Notes,$A9)&"")
A10: =IFERROR(MATCH(ROW()-5,c_Seq,0),"") -> 5 | B10: =IF($A10="","",INDEX(c_Name,$A10)&"") -> Chenise Lim | C10: =IF($A10="","",INDEX(c_Firm,$A10)&"") -> Financial Alliance | D10: =IF($A10="","",INDEX(c_Type,$A10)&"") -> Adviser | E10: =IF($A10="","",INDEX(c_Email,$A10)&"") -> cheniselim@fapl.sg | F10: =IF($A10="","",INDEX(c_Met,$A10)&"") -> Yes | G10: =IF($A10="","",IF(INDEX(c_Date,$A10)="","",INDEX(c_Date,$A10))) -> 45923 | H10: =IF($A10="","",IF(INDEX(c_Days,$A10)="","",INDEX(c_Days,$A10))) -> 318 | I10: =IF($A10="","",IF(INDEX(c_Mtgs,$A10)="","",INDEX(c_Mtgs,$A10))) -> 1 | J10: =IF($A10="","",INDEX(c_EvtNames,$A10)&"") | K10: =IF($A10="","",INDEX(c_Invested,$A10)&"") -> No | L10: =IF($A10="","",IF(INDEX(c_AUM,$A10)="","",INDEX(c_AUM,$A10))) -> 32000000 | M10: =IF($A10="","",INDEX(c_Source,$A10)&"") -> Meeting List + ILP Data | N10: =IF($A10="","",INDEX(c_Notes,$A10)&"") -> May-26: not available
A11: =IFERROR(MATCH(ROW()-5,c_Seq,0),"") -> 6 | B11: =IF($A11="","",INDEX(c_Name,$A11)&"") -> Edmond Goh | C11: =IF($A11="","",INDEX(c_Firm,$A11)&"") -> Financial Alliance | D11: =IF($A11="","",INDEX(c_Type,$A11)&"") -> Adviser | E11: =IF($A11="","",INDEX(c_Email,$A11)&"") -> edmondgoh@fapl.sg | F11: =IF($A11="","",INDEX(c_Met,$A11)&"") -> Yes | G11: =IF($A11="","",IF(INDEX(c_Date,$A11)="","",INDEX(c_Date,$A11))) -> 45918 | H11: =IF($A11="","",IF(INDEX(c_Days,$A11)="","",INDEX(c_Days,$A11))) -> 323 | I11: =IF($A11="","",IF(INDEX(c_Mtgs,$A11)="","",INDEX(c_Mtgs,$A11))) -> 1 | J11: =IF($A11="","",INDEX(c_EvtNames,$A11)&"") -> Oct-25 Symposium, May-26 Symposium | K11: =IF($A11="","",INDEX(c_Invested,$A11)&"") -> No | L11: =IF($A11="","",IF(INDEX(c_AUM,$A11)="","",INDEX(c_AUM,$A11))) -> 6000000 | M11: =IF($A11="","",INDEX(c_Source,$A11)&"") -> Meeting List + ILP Data | N11: =IF($A11="","",INDEX(c_Notes,$A11)&"")
A12: =IFERROR(MATCH(ROW()-5,c_Seq,0),"") -> 7 | B12: =IF($A12="","",INDEX(c_Name,$A12)&"") -> Edwin Tan | C12: =IF($A12="","",INDEX(c_Firm,$A12)&"") -> Financial Alliance | D12: =IF($A12="","",INDEX(c_Type,$A12)&"") -> Adviser | E12: =IF($A12="","",INDEX(c_Email,$A12)&"") -> edwintan@fapl.sg | F12: =IF($A12="","",INDEX(c_Met,$A12)&"") -> No | G12: =IF($A12="","",IF(INDEX(c_Date,$A12)="","",INDEX(c_Date,$A12))) | H12: =IF($A12="","",IF(INDEX(c_Days,$A12)="","",INDEX(c_Days,$A12))) | I12: =IF($A12="","",IF(INDEX(c_Mtgs,$A12)="","",INDEX(c_Mtgs,$A12))) -> 0 | J12: =IF($A12="","",INDEX(c_EvtNames,$A12)&"") -> May-26 Symposium | K12: =IF($A12="","",INDEX(c_Invested,$A12)&"") -> No | L12: =IF($A12="","",IF(INDEX(c_AUM,$A12)="","",INDEX(c_AUM,$A12))) | M12: =IF($A12="","",INDEX(c_Source,$A12)&"") -> Meeting List | N12: =IF($A12="","",INDEX(c_Notes,$A12)&"")
A13: =IFERROR(MATCH(ROW()-5,c_Seq,0),"") -> 8 | B13: =IF($A13="","",INDEX(c_Name,$A13)&"") -> Francis Hoan | C13: =IF($A13="","",INDEX(c_Firm,$A13)&"") -> Financial Alliance | D13: =IF($A13="","",INDEX(c_Type,$A13)&"") -> Adviser | E13: =IF($A13="","",INDEX(c_Email,$A13)&"") -> francishoan@fapl.sg | F13: =IF($A13="","",INDEX(c_Met,$A13)&"") -> No | G13: =IF($A13="","",IF(INDEX(c_Date,$A13)="","",INDEX(c_Date,$A13))) | H13: =IF($A13="","",IF(INDEX(c_Days,$A13)="","",INDEX(c_Days,$A13))) | I13: =IF($A13="","",IF(INDEX(c_Mtgs,$A13)="","",INDEX(c_Mtgs,$A13))) -> 0 | J13: =IF($A13="","",INDEX(c_EvtNames,$A13)&"") | K13: =IF($A13="","",INDEX(c_Invested,$A13)&"") -> No | L13: =IF($A13="","",IF(INDEX(c_AUM,$A13)="","",INDEX(c_AUM,$A13))) | M13: =IF($A13="","",INDEX(c_Source,$A13)&"") -> Meeting List | N13: =IF($A13="","",INDEX(c_Notes,$A13)&"")
A14: =IFERROR(MATCH(ROW()-5,c_Seq,0),"") -> 9 | B14: =IF($A14="","",INDEX(c_Name,$A14)&"") -> Gary Lim | C14: =IF($A14="","",INDEX(c_Firm,$A14)&"") -> Financial Alliance | D14: =IF($A14="","",INDEX(c_Type,$A14)&"") -> Adviser | E14: =IF($A14="","",INDEX(c_Email,$A14)&"") -> garylim@fapl.sg | F14: =IF($A14="","",INDEX(c_Met,$A14)&"") -> No | G14: =IF($A14="","",IF(INDEX(c_Date,$A14)="","",INDEX(c_Date,$A14))) | H14: =IF($A14="","",IF(INDEX(c_Days,$A14)="","",INDEX(c_Days,$A14))) | I14: =IF($A14="","",IF(INDEX(c_Mtgs,$A14)="","",INDEX(c_Mtgs,$A14))) -> 0 | J14: =IF($A14="","",INDEX(c_EvtNames,$A14)&"") -> Oct-25 Symposium | K14: =IF($A14="","",INDEX(c_Invested,$A14)&"") -> No | L14: =IF($A14="","",IF(INDEX(c_AUM,$A14)="","",INDEX(c_AUM,$A14))) -> 10000000 | M14: =IF($A14="","",INDEX(c_Source,$A14)&"") -> Meeting List + ILP Data | N14: =IF($A14="","",INDEX(c_Notes,$A14)&"")
A15: =IFERROR(MATCH(ROW()-5,c_Seq,0),"") -> 10 | B15: =IF($A15="","",INDEX(c_Name,$A15)&"") -> Guek Choo | C15: =IF($A15="","",INDEX(c_Firm,$A15)&"") -> Financial Alliance | D15: =IF($A15="","",INDEX(c_Type,$A15)&"") -> Adviser | E15: =IF($A15="","",INDEX(c_Email,$A15)&"") -> guekchoo@fapl.sg | F15: =IF($A15="","",INDEX(c_Met,$A15)&"") -> Yes | G15: =IF($A15="","",IF(INDEX(c_Date,$A15)="","",INDEX(c_Date,$A15))) -> 45923 | H15: =IF($A15="","",IF(INDEX(c_Days,$A15)="","",INDEX(c_Days,$A15))) -> 318 | I15: =IF($A15="","",IF(INDEX(c_Mtgs,$A15)="","",INDEX(c_Mtgs,$A15))) -> 1 | J15: =IF($A15="","",INDEX(c_EvtNames,$A15)&"") | K15: =IF($A15="","",INDEX(c_Invested,$A15)&"") -> No | L15: =IF($A15="","",IF(INDEX(c_AUM,$A15)="","",INDEX(c_AUM,$A15))) -> 4000000 | M15: =IF($A15="","",INDEX(c_Source,$A15)&"") -> Meeting List + ILP Data | N15: =IF($A15="","",INDEX(c_Notes,$A15)&"") -> May-26: not available
A16: =IFERROR(MATCH(ROW()-5,c_Seq,0),"") -> 11 | B16: =IF($A16="","",INDEX(c_Name,$A16)&"") -> Hadi Wijaya | C16: =IF($A16="","",INDEX(c_Firm,$A16)&"") -> Financial Alliance | D16: =IF($A16="","",INDEX(c_Type,$A16)&"") -> Adviser | E16: =IF($A16="","",INDEX(c_Email,$A16)&"") -> hadiwijaya@fapl.sg | F16: =IF($A16="","",INDEX(c_Met,$A16)&"") -> No | G16: =IF($A16="","",IF(INDEX(c_Date,$A16)="","",INDEX(c_Date,$A16))) | H16: =IF($A16="","",IF(INDEX(c_Days,$A16)="","",INDEX(c_Days,$A16))) | I16: =IF($A16="","",IF(INDEX(c_Mtgs,$A16)="","",INDEX(c_Mtgs,$A16))) -> 0 | J16: =IF($A16="","",INDEX(c_EvtNames,$A16)&"") | K16: =IF($A16="","",INDEX(c_Invested,$A16)&"") -> No | L16: =IF($A16="","",IF(INDEX(c_AUM,$A16)="","",INDEX(c_AUM,$A16))) | M16: =IF($A16="","",INDEX(c_Source,$A16)&"") -> Meeting List | N16: =IF($A16="","",INDEX(c_Notes,$A16)&"")
A17: =IFERROR(MATCH(ROW()-5,c_Seq,0),"") -> 12 | B17: =IF($A17="","",INDEX(c_Name,$A17)&"") -> Isaac Tang | C17: =IF($A17="","",INDEX(c_Firm,$A17)&"") -> Financial Alliance | D17: =IF($A17="","",INDEX(c_Type,$A17)&"") -> Adviser | E17: =IF($A17="","",INDEX(c_Email,$A17)&"") -> isaactang@fa.sg | F17: =IF($A17="","",INDEX(c_Met,$A17)&"") -> No | G17: =IF($A17="","",IF(INDEX(c_Date,$A17)="","",INDEX(c_Date,$A17))) | H17: =IF($A17="","",IF(INDEX(c_Days,$A17)="","",INDEX(c_Days,$A17))) | I17: =IF($A17="","",IF(INDEX(c_Mtgs,$A17)="","",INDEX(c_Mtgs,$A17))) -> 0 | J17: =IF($A17="","",INDEX(c_EvtNames,$A17)&"") -> May-26 Symposium | K17: =IF($A17="","",INDEX(c_Invested,$A17)&"") -> No | L17: =IF($A17="","",IF(INDEX(c_AUM,$A17)="","",INDEX(c_AUM,$A17))) | M17: =IF($A17="","",INDEX(c_Source,$A17)&"") -> Meeting List | N17: =IF($A17="","",INDEX(c_Notes,$A17)&"")
... A605: =IFERROR(MATCH(ROW()-5,c_Seq,0),"") | B605: =IF($A605="","",INDEX(c_Name,$A605)&"") | C605: =IF($A605="","",INDEX(c_Firm,$A605)&"") | D605: =IF($A605="","",INDEX(c_Type,$A605)&"") | E605: =IF($A605="","",INDEX(c_Email,$A605)&"") | F605: =IF($A605="","",INDEX(c_Met,$A605)&"") | G605: =IF($A605="","",IF(INDEX(c_Date,$A605)="","",INDEX(c_Date,$A605))) | H605: =IF($A605="","",IF(INDEX(c_Days,$A605)="","",INDEX(c_Days,$A605))) | I605: =IF($A605="","",IF(INDEX(c_Mtgs,$A605)="","",INDEX(c_Mtgs,$A605))) | J605: =IF($A605="","",INDEX(c_EvtNames,$A605)&"") | K605: =IF($A605="","",INDEX(c_Invested,$A605)&"") | L605: =IF($A605="","",IF(INDEX(c_AUM,$A605)="","",INDEX(c_AUM,$A605))) | M605: =IF($A605="","",INDEX(c_Source,$A605)&"") | N605: =IF($A605="","",INDEX(c_Notes,$A605)&"")

Sheet RawData
A1: ID | B1: Name | C1: Email | D1: Firm | E1: Contact Type | F1: Source | G1: Met? | H1: Last Meeting | I1: # Meetings | J1: Invested? | K1: AUM (S$) | L1: Email Sent | M1: LinkedIn Contacted | N1: =IF(Setup!$C$15="","Event 1 (free — name it in Setup)",Setup!$C$15) -> H2O AM IFA Symposium (October 2025) | O1: =IF(Setup!$C$16="","Event 2 (free — name it in Setup)",Setup!$C$16) -> 2nd Edition H2O AM IFA Symposium (May 2026) | P1: =IF(Setup!$C$17="","Event 3 (free — name it in Setup)",Setup!$C$17) -> Macro Lunch series | Q1: =IF(Setup!$C$18="","Event 4 (free — name it in Setup)",Setup!$C$18) -> Event 4 (free — name it in Setup) | R1: =IF(Setup!$C$19="","Event 5 (free — name it in Setup)",Setup!$C$19) -> Event 5 (free — name it in Setup) | S1: Notes | T1: # Events Invited | U1: # Events Attended | V1: Events Attended | W1: Days Since Meeting | X1: Engagement | Y1: _sort | Z1: _pass | AA1: _seq | AB1: _followup
A2: =IF($B2="","",COUNTA($B$2:$B2)) -> 1 | B2: Ang hui | C2: anghuichin@awfa.com.sg | D2: Alpha Wealth | E2: Adviser | F2: Meeting List | G2: No | I2: 0 | J2: No | N2: Not Invited | O2: No Show | P2: Not Invited | Q2: Not Invited | R2: Not Invited | T2: =IF($B2="","",COUNTA($N2:$R2)-COUNTIF($N2:$R2,"Not Invited")) -> 1 | U2: =IF($B2="","",COUNTIF($N2:$R2,"Attended")) -> 0 | V2: =IF($B2="","",_xlfn.TEXTJOIN(", ",TRUE(),IF($N2="Attended",Setup!$D$15,""),IF($O2="Attended",Setup!$D$16,""),IF($P2="Attended",Setup!$D$17,""),IF($Q2="Attended",Setup!$D$18,""),IF($R2="Attended",Setup!$D$19,""))) | W2: =IF(OR($B2="",NOT(ISNUMBER($H2))),"",TODAY()-$H2) | X2: =IF($B2="","",IF($U2>0,"Event attendee",IF($G2="Yes","Met (no event)",IF($T2>0,"Invited only",IF(OR($L2="Yes",$M2="Yes"),"Contacted only","Not yet contacted"))))) -> Invited only | Y2: =IF($B2="","",COUNTIF(c_Firm,"<"&$D2)+COUNTIFS(c_Firm,$D2,c_Name,"<"&$B2)+COUNTIFS($D$2:$D2,$D2,$B$2:$B2,$B2)) -> 1 | Z2: =IF($B2="","",IF(AND(OR(Contacts!$C$3="(All)",$D2=Contacts!$C$3),OR(Contacts!$E$3="(All)",$G2=Contacts!$E$3),OR(Contacts!$G$3="(All)",ISNUMBER(SEARCH(Contacts!$G$3,$V2))),OR(Contacts!$I$3="(All)",$X2=Contacts!$I$3),OR(Contacts!$K$3="",ISNUMBER(SEARCH(Contacts!$K$3,$B2&" "&$C2&" "&$D2&" "&$S2)))),1,0)) -> 1 | AA2: =IF($Z2=1,COUNTIFS(c_Pass,1,c_Sort,"<="&$Y2),"") -> 1 | AB2: =IF(OR($G2<>"Yes",NOT(ISNUMBER($H2))),"",COUNTIFS(c_Met,"Yes",c_Date,"<"&$H2)+COUNTIFS($G$2:$G2,"Yes",$H$2:$H2,$H2))
A3: =IF($B3="","",COUNTA($B$2:$B3)) -> 2 | B3: Jason Yin | C3: jasonyin@awfa.com.sg | D3: Alpha Wealth | E3: Adviser | F3: Meeting List | G3: No | I3: 0 | J3: No | N3: Not Invited | O3: Attended | P3: Not Invited | Q3: Not Invited | R3: Not Invited | T3: =IF($B3="","",COUNTA($N3:$R3)-COUNTIF($N3:$R3,"Not Invited")) -> 1 | U3: =IF($B3="","",COUNTIF($N3:$R3,"Attended")) -> 1 | V3: =IF($B3="","",_xlfn.TEXTJOIN(", ",TRUE(),IF($N3="Attended",Setup!$D$15,""),IF($O3="Attended",Setup!$D$16,""),IF($P3="Attended",Setup!$D$17,""),IF($Q3="Attended",Setup!$D$18,""),IF($R3="Attended",Setup!$D$19,""))) -> May-26 Symposium | W3: =IF(OR($B3="",NOT(ISNUMBER($H3))),"",TODAY()-$H3) | X3: =IF($B3="","",IF($U3>0,"Event attendee",IF($G3="Yes","Met (no event)",IF($T3>0,"Invited only",IF(OR($L3="Yes",$M3="Yes"),"Contacted only","Not yet contacted"))))) -> Event attendee | Y3: =IF($B3="","",COUNTIF(c_Firm,"<"&$D3)+COUNTIFS(c_Firm,$D3,c_Name,"<"&$B3)+COUNTIFS($D$2:$D3,$D3,$B$2:$B3,$B3)) -> 2 | Z3: =IF($B3="","",IF(AND(OR(Contacts!$C$3="(All)",$D3=Contacts!$C$3),OR(Contacts!$E$3="(All)",$G3=Contacts!$E$3),OR(Contacts!$G$3="(All)",ISNUMBER(SEARCH(Contacts!$G$3,$V3))),OR(Contacts!$I$3="(All)",$X3=Contacts!$I$3),OR(Contacts!$K$3="",ISNUMBER(SEARCH(Contacts!$K$3,$B3&" "&$C3&" "&$D3&" "&$S3)))),1,0)) -> 1 | AA3: =IF($Z3=1,COUNTIFS(c_Pass,1,c_Sort,"<="&$Y3),"") -> 2 | AB3: =IF(OR($G3<>"Yes",NOT(ISNUMBER($H3))),"",COUNTIFS(c_Met,"Yes",c_Date,"<"&$H3)+COUNTIFS($G$2:$G3,"Yes",$H$2:$H3,$H3))
A4: =IF($B4="","",COUNTA($B$2:$B4)) -> 3 | B4: Lee Jia Hao | C4: leejiahao@awfa.com.sg | D4: Alpha Wealth | E4: Adviser | F4: Meeting List | G4: No | I4: 0 | J4: No | N4: Not Invited | O4: Attended | P4: Not Invited | Q4: Not Invited | R4: Not Invited | T4: =IF($B4="","",COUNTA($N4:$R4)-COUNTIF($N4:$R4,"Not Invited")) -> 1 | U4: =IF($B4="","",COUNTIF($N4:$R4,"Attended")) -> 1 | V4: =IF($B4="","",_xlfn.TEXTJOIN(", ",TRUE(),IF($N4="Attended",Setup!$D$15,""),IF($O4="Attended",Setup!$D$16,""),IF($P4="Attended",Setup!$D$17,""),IF($Q4="Attended",Setup!$D$18,""),IF($R4="Attended",Setup!$D$19,""))) -> May-26 Symposium | W4: =IF(OR($B4="",NOT(ISNUMBER($H4))),"",TODAY()-$H4) | X4: =IF($B4="","",IF($U4>0,"Event attendee",IF($G4="Yes","Met (no event)",IF($T4>0,"Invited only",IF(OR($L4="Yes",$M4="Yes"),"Contacted only","Not yet contacted"))))) -> Event attendee | Y4: =IF($B4="","",COUNTIF(c_Firm,"<"&$D4)+COUNTIFS(c_Firm,$D4,c_Name,"<"&$B4)+COUNTIFS($D$2:$D4,$D4,$B$2:$B4,$B4)) -> 3 | Z4: =IF($B4="","",IF(AND(OR(Contacts!$C$3="(All)",$D4=Contacts!$C$3),OR(Contacts!$E$3="(All)",$G4=Contacts!$E$3),OR(Contacts!$G$3="(All)",ISNUMBER(SEARCH(Contacts!$G$3,$V4))),OR(Contacts!$I$3="(All)",$X4=Contacts!$I$3),OR(Contacts!$K$3="",ISNUMBER(SEARCH(Contacts!$K$3,$B4&" "&$C4&" "&$D4&" "&$S4)))),1,0)) -> 1 | AA4: =IF($Z4=1,COUNTIFS(c_Pass,1,c_Sort,"<="&$Y4),"") -> 3 | AB4: =IF(OR($G4<>"Yes",NOT(ISNUMBER($H4))),"",COUNTIFS(c_Met,"Yes",c_Date,"<"&$H4)+COUNTIFS($G$2:$G4,"Yes",$H$2:$H4,$H4))
A5: =IF($B5="","",COUNTA($B$2:$B5)) -> 4 | B5: Alvin Low | C5: alvinlow@fapl.sg | D5: Financial Alliance | E5: Adviser | F5: Meeting List + ILP Data | G5: Yes | H5: 45918 | I5: 1 | J5: No | K5: 5000000 | N5: Declined | O5: No Reply | P5: Not Invited | Q5: Not Invited | R5: Not Invited | T5: =IF($B5="","",COUNTA($N5:$R5)-COUNTIF($N5:$R5,"Not Invited")) -> 2 | U5: =IF($B5="","",COUNTIF($N5:$R5,"Attended")) -> 0 | V5: =IF($B5="","",_xlfn.TEXTJOIN(", ",TRUE(),IF($N5="Attended",Setup!$D$15,""),IF($O5="Attended",Setup!$D$16,""),IF($P5="Attended",Setup!$D$17,""),IF($Q5="Attended",Setup!$D$18,""),IF($R5="Attended",Setup!$D$19,""))) | W5: =IF(OR($B5="",NOT(ISNUMBER($H5))),"",TODAY()-$H5) -> 323 | X5: =IF($B5="","",IF($U5>0,"Event attendee",IF($G5="Yes","Met (no event)",IF($T5>0,"Invited only",IF(OR($L5="Yes",$M5="Yes"),"Contacted only","Not yet contacted"))))) -> Met (no event) | Y5: =IF($B5="","",COUNTIF(c_Firm,"<"&$D5)+COUNTIFS(c_Firm,$D5,c_Name,"<"&$B5)+COUNTIFS($D$2:$D5,$D5,$B$2:$B5,$B5)) -> 4 | Z5: =IF($B5="","",IF(AND(OR(Contacts!$C$3="(All)",$D5=Contacts!$C$3),OR(Contacts!$E$3="(All)",$G5=Contacts!$E$3),OR(Contacts!$G$3="(All)",ISNUMBER(SEARCH(Contacts!$G$3,$V5))),OR(Contacts!$I$3="(All)",$X5=Contacts!$I$3),OR(Contacts!$K$3="",ISNUMBER(SEARCH(Contacts!$K$3,$B5&" "&$C5&" "&$D5&" "&$S5)))),1,0)) -> 1 | AA5: =IF($Z5=1,COUNTIFS(c_Pass,1,c_Sort,"<="&$Y5),"") -> 4 | AB5: =IF(OR($G5<>"Yes",NOT(ISNUMBER($H5))),"",COUNTIFS(c_Met,"Yes",c_Date,"<"&$H5)+COUNTIFS($G$2:$G5,"Yes",$H$2:$H5,$H5)) -> 14
A6: =IF($B6="","",COUNTA($B$2:$B6)) -> 5 | B6: Chenise Lim | C6: cheniselim@fapl.sg | D6: Financial Alliance | E6: Adviser | F6: Meeting List + ILP Data | G6: Yes | H6: 45923 | I6: 1 | J6: No | K6: 32000000 | N6: Declined | O6: Declined | P6: Not Invited | Q6: Not Invited | R6: Not Invited | S6: May-26: not available | T6: =IF($B6="","",COUNTA($N6:$R6)-COUNTIF($N6:$R6,"Not Invited")) -> 2 | U6: =IF($B6="","",COUNTIF($N6:$R6,"Attended")) -> 0 | V6: =IF($B6="","",_xlfn.TEXTJOIN(", ",TRUE(),IF($N6="Attended",Setup!$D$15,""),IF($O6="Attended",Setup!$D$16,""),IF($P6="Attended",Setup!$D$17,""),IF($Q6="Attended",Setup!$D$18,""),IF($R6="Attended",Setup!$D$19,""))) | W6: =IF(OR($B6="",NOT(ISNUMBER($H6))),"",TODAY()-$H6) -> 318 | X6: =IF($B6="","",IF($U6>0,"Event attendee",IF($G6="Yes","Met (no event)",IF($T6>0,"Invited only",IF(OR($L6="Yes",$M6="Yes"),"Contacted only","Not yet contacted"))))) -> Met (no event) | Y6: =IF($B6="","",COUNTIF(c_Firm,"<"&$D6)+COUNTIFS(c_Firm,$D6,c_Name,"<"&$B6)+COUNTIFS($D$2:$D6,$D6,$B$2:$B6,$B6)) -> 5 | Z6: =IF($B6="","",IF(AND(OR(Contacts!$C$3="(All)",$D6=Contacts!$C$3),OR(Contacts!$E$3="(All)",$G6=Contacts!$E$3),OR(Contacts!$G$3="(All)",ISNUMBER(SEARCH(Contacts!$G$3,$V6))),OR(Contacts!$I$3="(All)",$X6=Contacts!$I$3),OR(Contacts!$K$3="",ISNUMBER(SEARCH(Contacts!$K$3,$B6&" "&$C6&" "&$D6&" "&$S6)))),1,0)) -> 1 | AA6: =IF($Z6=1,COUNTIFS(c_Pass,1,c_Sort,"<="&$Y6),"") -> 5 | AB6: =IF(OR($G6<>"Yes",NOT(ISNUMBER($H6))),"",COUNTIFS(c_Met,"Yes",c_Date,"<"&$H6)+COUNTIFS($G$2:$G6,"Yes",$H$2:$H6,$H6)) -> 18
A7: =IF($B7="","",COUNTA($B$2:$B7)) -> 6 | B7: Edmond Goh | C7: edmondgoh@fapl.sg | D7: Financial Alliance | E7: Adviser | F7: Meeting List + ILP Data | G7: Yes | H7: 45918 | I7: 1 | J7: No | K7: 6000000 | N7: Attended | O7: Attended | P7: Not Invited | Q7: Not Invited | R7: Not Invited | T7: =IF($B7="","",COUNTA($N7:$R7)-COUNTIF($N7:$R7,"Not Invited")) -> 2 | U7: =IF($B7="","",COUNTIF($N7:$R7,"Attended")) -> 2 | V7: =IF($B7="","",_xlfn.TEXTJOIN(", ",TRUE(),IF($N7="Attended",Setup!$D$15,""),IF($O7="Attended",Setup!$D$16,""),IF($P7="Attended",Setup!$D$17,""),IF($Q7="Attended",Setup!$D$18,""),IF($R7="Attended",Setup!$D$19,""))) -> Oct-25 Symposium, May-26 Symposium | W7: =IF(OR($B7="",NOT(ISNUMBER($H7))),"",TODAY()-$H7) -> 323 | X7: =IF($B7="","",IF($U7>0,"Event attendee",IF($G7="Yes","Met (no event)",IF($T7>0,"Invited only",IF(OR($L7="Yes",$M7="Yes"),"Contacted only","Not yet contacted"))))) -> Event attendee | Y7: =IF($B7="","",COUNTIF(c_Firm,"<"&$D7)+COUNTIFS(c_Firm,$D7,c_Name,"<"&$B7)+COUNTIFS($D$2:$D7,$D7,$B$2:$B7,$B7)) -> 6 | Z7: =IF($B7="","",IF(AND(OR(Contacts!$C$3="(All)",$D7=Contacts!$C$3),OR(Contacts!$E$3="(All)",$G7=Contacts!$E$3),OR(Contacts!$G$3="(All)",ISNUMBER(SEARCH(Contacts!$G$3,$V7))),OR(Contacts!$I$3="(All)",$X7=Contacts!$I$3),OR(Contacts!$K$3="",ISNUMBER(SEARCH(Contacts!$K$3,$B7&" "&$C7&" "&$D7&" "&$S7)))),1,0)) -> 1 | AA7: =IF($Z7=1,COUNTIFS(c_Pass,1,c_Sort,"<="&$Y7),"") -> 6 | AB7: =IF(OR($G7<>"Yes",NOT(ISNUMBER($H7))),"",COUNTIFS(c_Met,"Yes",c_Date,"<"&$H7)+COUNTIFS($G$2:$G7,"Yes",$H$2:$H7,$H7)) -> 15
A8: =IF($B8="","",COUNTA($B$2:$B8)) -> 7 | B8: Edwin Tan | C8: edwintan@fapl.sg | D8: Financial Alliance | E8: Adviser | F8: Meeting List | G8: No | I8: 0 | J8: No | N8: Not Invited | O8: Attended | P8: Not Invited | Q8: Not Invited | R8: Not Invited | T8: =IF($B8="","",COUNTA($N8:$R8)-COUNTIF($N8:$R8,"Not Invited")) -> 1 | U8: =IF($B8="","",COUNTIF($N8:$R8,"Attended")) -> 1 | V8: =IF($B8="","",_xlfn.TEXTJOIN(", ",TRUE(),IF($N8="Attended",Setup!$D$15,""),IF($O8="Attended",Setup!$D$16,""),IF($P8="Attended",Setup!$D$17,""),IF($Q8="Attended",Setup!$D$18,""),IF($R8="Attended",Setup!$D$19,""))) -> May-26 Symposium | W8: =IF(OR($B8="",NOT(ISNUMBER($H8))),"",TODAY()-$H8) | X8: =IF($B8="","",IF($U8>0,"Event attendee",IF($G8="Yes","Met (no event)",IF($T8>0,"Invited only",IF(OR($L8="Yes",$M8="Yes"),"Contacted only","Not yet contacted"))))) -> Event attendee | Y8: =IF($B8="","",COUNTIF(c_Firm,"<"&$D8)+COUNTIFS(c_Firm,$D8,c_Name,"<"&$B8)+COUNTIFS($D$2:$D8,$D8,$B$2:$B8,$B8)) -> 7 | Z8: =IF($B8="","",IF(AND(OR(Contacts!$C$3="(All)",$D8=Contacts!$C$3),OR(Contacts!$E$3="(All)",$G8=Contacts!$E$3),OR(Contacts!$G$3="(All)",ISNUMBER(SEARCH(Contacts!$G$3,$V8))),OR(Contacts!$I$3="(All)",$X8=Contacts!$I$3),OR(Contacts!$K$3="",ISNUMBER(SEARCH(Contacts!$K$3,$B8&" "&$C8&" "&$D8&" "&$S8)))),1,0)) -> 1 | AA8: =IF($Z8=1,COUNTIFS(c_Pass,1,c_Sort,"<="&$Y8),"") -> 7 | AB8: =IF(OR($G8<>"Yes",NOT(ISNUMBER($H8))),"",COUNTIFS(c_Met,"Yes",c_Date,"<"&$H8)+COUNTIFS($G$2:$G8,"Yes",$H$2:$H8,$H8))
A9: =IF($B9="","",COUNTA($B$2:$B9)) -> 8 | B9: Francis Hoan | C9: francishoan@fapl.sg | D9: Financial Alliance | E9: Adviser | F9: Meeting List | G9: No | I9: 0 | J9: No | N9: Not Invited | O9: Declined | P9: Not Invited | Q9: Not Invited | R9: Not Invited | T9: =IF($B9="","",COUNTA($N9:$R9)-COUNTIF($N9:$R9,"Not Invited")) -> 1 | U9: =IF($B9="","",COUNTIF($N9:$R9,"Attended")) -> 0 | V9: =IF($B9="","",_xlfn.TEXTJOIN(", ",TRUE(),IF($N9="Attended",Setup!$D$15,""),IF($O9="Attended",Setup!$D$16,""),IF($P9="Attended",Setup!$D$17,""),IF($Q9="Attended",Setup!$D$18,""),IF($R9="Attended",Setup!$D$19,""))) | W9: =IF(OR($B9="",NOT(ISNUMBER($H9))),"",TODAY()-$H9) | X9: =IF($B9="","",IF($U9>0,"Event attendee",IF($G9="Yes","Met (no event)",IF($T9>0,"Invited only",IF(OR($L9="Yes",$M9="Yes"),"Contacted only","Not yet contacted"))))) -> Invited only | Y9: =IF($B9="","",COUNTIF(c_Firm,"<"&$D9)+COUNTIFS(c_Firm,$D9,c_Name,"<"&$B9)+COUNTIFS($D$2:$D9,$D9,$B$2:$B9,$B9)) -> 8 | Z9: =IF($B9="","",IF(AND(OR(Contacts!$C$3="(All)",$D9=Contacts!$C$3),OR(Contacts!$E$3="(All)",$G9=Contacts!$E$3),OR(Contacts!$G$3="(All)",ISNUMBER(SEARCH(Contacts!$G$3,$V9))),OR(Contacts!$I$3="(All)",$X9=Contacts!$I$3),OR(Contacts!$K$3="",ISNUMBER(SEARCH(Contacts!$K$3,$B9&" "&$C9&" "&$D9&" "&$S9)))),1,0)) -> 1 | AA9: =IF($Z9=1,COUNTIFS(c_Pass,1,c_Sort,"<="&$Y9),"") -> 8 | AB9: =IF(OR($G9<>"Yes",NOT(ISNUMBER($H9))),"",COUNTIFS(c_Met,"Yes",c_Date,"<"&$H9)+COUNTIFS($G$2:$G9,"Yes",$H$2:$H9,$H9))
A10: =IF($B10="","",COUNTA($B$2:$B10)) -> 9 | B10: Gary Lim | C10: garylim@fapl.sg | D10: Financial Alliance | E10: Adviser | F10: Meeting List + ILP Data | G10: No | I10: 0 | J10: No | K10: 10000000 | N10: Attended | O10: Declined | P10: Not Invited | Q10: Not Invited | R10: Not Invited | T10: =IF($B10="","",COUNTA($N10:$R10)-COUNTIF($N10:$R10,"Not Invited")) -> 2 | U10: =IF($B10="","",COUNTIF($N10:$R10,"Attended")) -> 1 | V10: =IF($B10="","",_xlfn.TEXTJOIN(", ",TRUE(),IF($N10="Attended",Setup!$D$15,""),IF($O10="Attended",Setup!$D$16,""),IF($P10="Attended",Setup!$D$17,""),IF($Q10="Attended",Setup!$D$18,""),IF($R10="Attended",Setup!$D$19,""))) -> Oct-25 Symposium | W10: =IF(OR($B10="",NOT(ISNUMBER($H10))),"",TODAY()-$H10) | X10: =IF($B10="","",IF($U10>0,"Event attendee",IF($G10="Yes","Met (no event)",IF($T10>0,"Invited only",IF(OR($L10="Yes",$M10="Yes"),"Contacted only","Not yet contacted"))))) -> Event attendee | Y10: =IF($B10="","",COUNTIF(c_Firm,"<"&$D10)+COUNTIFS(c_Firm,$D10,c_Name,"<"&$B10)+COUNTIFS($D$2:$D10,$D10,$B$2:$B10,$B10)) -> 9 | Z10: =IF($B10="","",IF(AND(OR(Contacts!$C$3="(All)",$D10=Contacts!$C$3),OR(Contacts!$E$3="(All)",$G10=Contacts!$E$3),OR(Contacts!$G$3="(All)",ISNUMBER(SEARCH(Contacts!$G$3,$V10))),OR(Contacts!$I$3="(All)",$X10=Contacts!$I$3),OR(Contacts!$K$3="",ISNUMBER(SEARCH(Contacts!$K$3,$B10&" "&$C10&" "&$D10&" "&$S10)))),1,0)) -> 1 | AA10: =IF($Z10=1,COUNTIFS(c_Pass,1,c_Sort,"<="&$Y10),"") -> 9 | AB10: =IF(OR($G10<>"Yes",NOT(ISNUMBER($H10))),"",COUNTIFS(c_Met,"Yes",c_Date,"<"&$H10)+COUNTIFS($G$2:$G10,"Yes",$H$2:$H10,$H10))
A11: =IF($B11="","",COUNTA($B$2:$B11)) -> 10 | B11: Guek Choo | C11: guekchoo@fapl.sg | D11: Financial Alliance | E11: Adviser | F11: Meeting List + ILP Data | G11: Yes | H11: 45923 | I11: 1 | J11: No | K11: 4000000 | N11: Declined | O11: Declined | P11: Not Invited | Q11: Not Invited | R11: Not Invited | S11: May-26: not available | T11: =IF($B11="","",COUNTA($N11:$R11)-COUNTIF($N11:$R11,"Not Invited")) -> 2 | U11: =IF($B11="","",COUNTIF($N11:$R11,"Attended")) -> 0 | V11: =IF($B11="","",_xlfn.TEXTJOIN(", ",TRUE(),IF($N11="Attended",Setup!$D$15,""),IF($O11="Attended",Setup!$D$16,""),IF($P11="Attended",Setup!$D$17,""),IF($Q11="Attended",Setup!$D$18,""),IF($R11="Attended",Setup!$D$19,""))) | W11: =IF(OR($B11="",NOT(ISNUMBER($H11))),"",TODAY()-$H11) -> 318 | X11: =IF($B11="","",IF($U11>0,"Event attendee",IF($G11="Yes","Met (no event)",IF($T11>0,"Invited only",IF(OR($L11="Yes",$M11="Yes"),"Contacted only","Not yet contacted"))))) -> Met (no event) | Y11: =IF($B11="","",COUNTIF(c_Firm,"<"&$D11)+COUNTIFS(c_Firm,$D11,c_Name,"<"&$B11)+COUNTIFS($D$2:$D11,$D11,$B$2:$B11,$B11)) -> 10 | Z11: =IF($B11="","",IF(AND(OR(Contacts!$C$3="(All)",$D11=Contacts!$C$3),OR(Contacts!$E$3="(All)",$G11=Contacts!$E$3),OR(Contacts!$G$3="(All)",ISNUMBER(SEARCH(Contacts!$G$3,$V11))),OR(Contacts!$I$3="(All)",$X11=Contacts!$I$3),OR(Contacts!$K$3="",ISNUMBER(SEARCH(Contacts!$K$3,$B11&" "&$C11&" "&$D11&" "&$S11)))),1,0)) -> 1 | AA11: =IF($Z11=1,COUNTIFS(c_Pass,1,c_Sort,"<="&$Y11),"") -> 10 | AB11: =IF(OR($G11<>"Yes",NOT(ISNUMBER($H11))),"",COUNTIFS(c_Met,"Yes",c_Date,"<"&$H11)+COUNTIFS($G$2:$G11,"Yes",$H$2:$H11,$H11)) -> 19
A12: =IF($B12="","",COUNTA($B$2:$B12)) -> 11 | B12: Hadi Wijaya | C12: hadiwijaya@fapl.sg | D12: Financial Alliance | E12: Adviser | F12: Meeting List | G12: No | I12: 0 | J12: No | N12: Not Invited | O12: No Reply | P12: Not Invited | Q12: Not Invited | R12: Not Invited | T12: =IF($B12="","",COUNTA($N12:$R12)-COUNTIF($N12:$R12,"Not Invited")) -> 1 | U12: =IF($B12="","",COUNTIF($N12:$R12,"Attended")) -> 0 | V12: =IF($B12="","",_xlfn.TEXTJOIN(", ",TRUE(),IF($N12="Attended",Setup!$D$15,""),IF($O12="Attended",Setup!$D$16,""),IF($P12="Attended",Setup!$D$17,""),IF($Q12="Attended",Setup!$D$18,""),IF($R12="Attended",Setup!$D$19,""))) | W12: =IF(OR($B12="",NOT(ISNUMBER($H12))),"",TODAY()-$H12) | X12: =IF($B12="","",IF($U12>0,"Event attendee",IF($G12="Yes","Met (no event)",IF($T12>0,"Invited only",IF(OR($L12="Yes",$M12="Yes"),"Contacted only","Not yet contacted"))))) -> Invited only | Y12: =IF($B12="","",COUNTIF(c_Firm,"<"&$D12)+COUNTIFS(c_Firm,$D12,c_Name,"<"&$B12)+COUNTIFS($D$2:$D12,$D12,$B$2:$B12,$B12)) -> 11 | Z12: =IF($B12="","",IF(AND(OR(Contacts!$C$3="(All)",$D12=Contacts!$C$3),OR(Contacts!$E$3="(All)",$G12=Contacts!$E$3),OR(Contacts!$G$3="(All)",ISNUMBER(SEARCH(Contacts!$G$3,$V12))),OR(Contacts!$I$3="(All)",$X12=Contacts!$I$3),OR(Contacts!$K$3="",ISNUMBER(SEARCH(Contacts!$K$3,$B12&" "&$C12&" "&$D12&" "&$S12)))),1,0)) -> 1 | AA12: =IF($Z12=1,COUNTIFS(c_Pass,1,c_Sort,"<="&$Y12),"") -> 11 | AB12: =IF(OR($G12<>"Yes",NOT(ISNUMBER($H12))),"",COUNTIFS(c_Met,"Yes",c_Date,"<"&$H12)+COUNTIFS($G$2:$G12,"Yes",$H$2:$H12,$H12))
A13: =IF($B13="","",COUNTA($B$2:$B13)) -> 12 | B13: Isaac Tang | C13: isaactang@fa.sg | D13: Financial Alliance | E13: Adviser | F13: Meeting List | G13: No | I13: 0 | J13: No | N13: Not Invited | O13: Attended | P13: Not Invited | Q13: Not Invited | R13: Not Invited | T13: =IF($B13="","",COUNTA($N13:$R13)-COUNTIF($N13:$R13,"Not Invited")) -> 1 | U13: =IF($B13="","",COUNTIF($N13:$R13,"Attended")) -> 1 | V13: =IF($B13="","",_xlfn.TEXTJOIN(", ",TRUE(),IF($N13="Attended",Setup!$D$15,""),IF($O13="Attended",Setup!$D$16,""),IF($P13="Attended",Setup!$D$17,""),IF($Q13="Attended",Setup!$D$18,""),IF($R13="Attended",Setup!$D$19,""))) -> May-26 Symposium | W13: =IF(OR($B13="",NOT(ISNUMBER($H13))),"",TODAY()-$H13) | X13: =IF($B13="","",IF($U13>0,"Event attendee",IF($G13="Yes","Met (no event)",IF($T13>0,"Invited only",IF(OR($L13="Yes",$M13="Yes"),"Contacted only","Not yet contacted"))))) -> Event attendee | Y13: =IF($B13="","",COUNTIF(c_Firm,"<"&$D13)+COUNTIFS(c_Firm,$D13,c_Name,"<"&$B13)+COUNTIFS($D$2:$D13,$D13,$B$2:$B13,$B13)) -> 12 | Z13: =IF($B13="","",IF(AND(OR(Contacts!$C$3="(All)",$D13=Contacts!$C$3),OR(Contacts!$E$3="(All)",$G13=Contacts!$E$3),OR(Contacts!$G$3="(All)",ISNUMBER(SEARCH(Contacts!$G$3,$V13))),OR(Contacts!$I$3="(All)",$X13=Contacts!$I$3),OR(Contacts!$K$3="",ISNUMBER(SEARCH(Contacts!$K$3,$B13&" "&$C13&" "&$D13&" "&$S13)))),1,0)) -> 1 | AA13: =IF($Z13=1,COUNTIFS(c_Pass,1,c_Sort,"<="&$Y13),"") -> 12 | AB13: =IF(OR($G13<>"Yes",NOT(ISNUMBER($H13))),"",COUNTIFS(c_Met,"Yes",c_Date,"<"&$H13)+COUNTIFS($G$2:$G13,"Yes",$H$2:$H13,$H13))
A14: =IF($B14="","",COUNTA($B$2:$B14)) -> 13 | B14: Kelvin Teng | C14: kelvinteng@fapl.sg | D14: Financial Alliance | E14: Adviser | F14: Meeting List | G14: No | I14: 0 | J14: No | N14: Not Invited | O14: Attended | P14: Not Invited | Q14: Not Invited | R14: Not Invited | T14: =IF($B14="","",COUNTA($N14:$R14)-COUNTIF($N14:$R14,"Not Invited")) -> 1 | U14: =IF($B14="","",COUNTIF($N14:$R14,"Attended")) -> 1 | V14: =IF($B14="","",_xlfn.TEXTJOIN(", ",TRUE(),IF($N14="Attended",Setup!$D$15,""),IF($O14="Attended",Setup!$D$16,""),IF($P14="Attended",Setup!$D$17,""),IF($Q14="Attended",Setup!$D$18,""),IF($R14="Attended",Setup!$D$19,""))) -> May-26 Symposium | W14: =IF(OR($B14="",NOT(ISNUMBER($H14))),"",TODAY()-$H14) | X14: =IF($B14="","",IF($U14>0,"Event attendee",IF($G14="Yes","Met (no event)",IF($T14>0,"Invited only",IF(OR($L14="Yes",$M14="Yes"),"Contacted only","Not yet contacted"))))) -> Event attendee | Y14: =IF($B14="","",COUNTIF(c_Firm,"<"&$D14)+COUNTIFS(c_Firm,$D14,c_Name,"<"&$B14)+COUNTIFS($D$2:$D14,$D14,$B$2:$B14,$B14)) -> 13 | Z14: =IF($B14="","",IF(AND(OR(Contacts!$C$3="(All)",$D14=Contacts!$C$3),OR(Contacts!$E$3="(All)",$G14=Contacts!$E$3),OR(Contacts!$G$3="(All)",ISNUMBER(SEARCH(Contacts!$G$3,$V14))),OR(Contacts!$I$3="(All)",$X14=Contacts!$I$3),OR(Contacts!$K$3="",ISNUMBER(SEARCH(Contacts!$K$3,$B14&" "&$C14&" "&$D14&" "&$S14)))),1,0)) -> 1 | AA14: =IF($Z14=1,COUNTIFS(c_Pass,1,c_Sort,"<="&$Y14),"") -> 13 | AB14: =IF(OR($G14<>"Yes",NOT(ISNUMBER($H14))),"",COUNTIFS(c_Met,"Yes",c_Date,"<"&$H14)+COUNTIFS($G$2:$G14,"Yes",$H$2:$H14,$H14))
A15: =IF($B15="","",COUNTA($B$2:$B15)) -> 14 | B15: Khairuddin Sukor | C15: khairuddin@fapl.sg | D15: Financial Alliance | E15: Adviser | F15: Meeting List + ILP Data | G15: Yes | H15: 45919 | I15: 1 | J15: No | K15: 5000000 | N15: Attended | O15: Declined | P15: Not Invited | Q15: Not Invited | R15: Not Invited | T15: =IF($B15="","",COUNTA($N15:$R15)-COUNTIF($N15:$R15,"Not Invited")) -> 2 | U15: =IF($B15="","",COUNTIF($N15:$R15,"Attended")) -> 1 | V15: =IF($B15="","",_xlfn.TEXTJOIN(", ",TRUE(),IF($N15="Attended",Setup!$D$15,""),IF($O15="Attended",Setup!$D$16,""),IF($P15="Attended",Setup!$D$17,""),IF($Q15="Attended",Setup!$D$18,""),IF($R15="Attended",Setup!$D$19,""))) -> Oct-25 Symposium | W15: =IF(OR($B15="",NOT(ISNUMBER($H15))),"",TODAY()-$H15) -> 322 | X15: =IF($B15="","",IF($U15>0,"Event attendee",IF($G15="Yes","Met (no event)",IF($T15>0,"Invited only",IF(OR($L15="Yes",$M15="Yes"),"Contacted only","Not yet contacted"))))) -> Event attendee | Y15: =IF($B15="","",COUNTIF(c_Firm,"<"&$D15)+COUNTIFS(c_Firm,$D15,c_Name,"<"&$B15)+COUNTIFS($D$2:$D15,$D15,$B$2:$B15,$B15)) -> 14 | Z15: =IF($B15="","",IF(AND(OR(Contacts!$C$3="(All)",$D15=Contacts!$C$3),OR(Contacts!$E$3="(All)",$G15=Contacts!$E$3),OR(Contacts!$G$3="(All)",ISNUMBER(SEARCH(Contacts!$G$3,$V15))),OR(Contacts!$I$3="(All)",$X15=Contacts!$I$3),OR(Contacts!$K$3="",ISNUMBER(SEARCH(Contacts!$K$3,$B15&" "&$C15&" "&$D15&" "&$S15)))),1,0)) -> 1 | AA15: =IF($Z15=1,COUNTIFS(c_Pass,1,c_Sort,"<="&$Y15),"") -> 14 | AB15: =IF(OR($G15<>"Yes",NOT(ISNUMBER($H15))),"",COUNTIFS(c_Met,"Yes",c_Date,"<"&$H15)+COUNTIFS($G$2:$G15,"Yes",$H$2:$H15,$H15)) -> 16
A16: =IF($B16="","",COUNTA($B$2:$B16)) -> 15 | B16: Mithun Malani | C16: mithunmalani@fapl.sg | D16: Financial Alliance | E16: Adviser | F16: Meeting List + ILP Data | G16: Yes | H16: 45965 | I16: 1 | J16: No | K16: 3000000 | N16: No Reply | O16: Attended | P16: Not Invited | Q16: Not Invited | R16: Not Invited | T16: =IF($B16="","",COUNTA($N16:$R16)-COUNTIF($N16:$R16,"Not Invited")) -> 2 | U16: =IF($B16="","",COUNTIF($N16:$R16,"Attended")) -> 1 | V16: =IF($B16="","",_xlfn.TEXTJOIN(", ",TRUE(),IF($N16="Attended",Setup!$D$15,""),IF($O16="Attended",Setup!$D$16,""),IF($P16="Attended",Setup!$D$17,""),IF($Q16="Attended",Setup!$D$18,""),IF($R16="Attended",Setup!$D$19,""))) -> May-26 Symposium | W16: =IF(OR($B16="",NOT(ISNUMBER($H16))),"",TODAY()-$H16) -> 276 | X16: =IF($B16="","",IF($U16>0,"Event attendee",IF($G16="Yes","Met (no event)",IF($T16>0,"Invited only",IF(OR($L16="Yes",$M16="Yes"),"Contacted only","Not yet contacted"))))) -> Event attendee | Y16: =IF($B16="","",COUNTIF(c_Firm,"<"&$D16)+COUNTIFS(c_Firm,$D16,c_Name,"<"&$B16)+COUNTIFS($D$2:$D16,$D16,$B$2:$B16,$B16)) -> 15 | Z16: =IF($B16="","",IF(AND(OR(Contacts!$C$3="(All)",$D16=Contacts!$C$3),OR(Contacts!$E$3="(All)",$G16=Contacts!$E$3),OR(Contacts!$G$3="(All)",ISNUMBER(SEARCH(Contacts!$G$3,$V16))),OR(Contacts!$I$3="(All)",$X16=Contacts!$I$3),OR(Contacts!$K$3="",ISNUMBER(SEARCH(Contacts!$K$3,$B16&" "&$C16&" "&$D16&" "&$S16)))),1,0)) -> 1 | AA16: =IF($Z16=1,COUNTIFS(c_Pass,1,c_Sort,"<="&$Y16),"") -> 15 | AB16: =IF(OR($G16<>"Yes",NOT(ISNUMBER($H16))),"",COUNTIFS(c_Met,"Yes",c_Date,"<"&$H16)+COUNTIFS($G$2:$G16,"Yes",$H$2:$H16,$H16)) -> 31
A17: =IF($B17="","",COUNTA($B$2:$B17)) -> 16 | B17: Nicholas Low | C17: lownicholas@fa.sg | D17: Financial Alliance | E17: Adviser | F17: Meeting List + ILP Data | G17: No | I17: 0 | J17: No | N17: Attended | O17: No Reply | P17: Not Invited | Q17: Not Invited | R17: Not Invited | S17: May-26: email bounced back; ILP: Investment | T17: =IF($B17="","",COUNTA($N17:$R17)-COUNTIF($N17:$R17,"Not Invited")) -> 2 | U17: =IF($B17="","",COUNTIF($N17:$R17,"Attended")) -> 1 | V17: =IF($B17="","",_xlfn.TEXTJOIN(", ",TRUE(),IF($N17="Attended",Setup!$D$15,""),IF($O17="Attended",Setup!$D$16,""),IF($P17="Attended",Setup!$D$17,""),IF($Q17="Attended",Setup!$D$18,""),IF($R17="Attended",Setup!$D$19,""))) -> Oct-25 Symposium | W17: =IF(OR($B17="",NOT(ISNUMBER($H17))),"",TODAY()-$H17) | X17: =IF($B17="","",IF($U17>0,"Event attendee",IF($G17="Yes","Met (no event)",IF($T17>0,"Invited only",IF(OR($L17="Yes",$M17="Yes"),"Contacted only","Not yet contacted"))))) -> Event attendee | Y17: =IF($B17="","",COUNTIF(c_Firm,"<"&$D17)+COUNTIFS(c_Firm,$D17,c_Name,"<"&$B17)+COUNTIFS($D$2:$D17,$D17,$B$2:$B17,$B17)) -> 16 | Z17: =IF($B17="","",IF(AND(OR(Contacts!$C$3="(All)",$D17=Contacts!$C$3),OR(Contacts!$E$3="(All)",$G17=Contacts!$E$3),OR(Contacts!$G$3="(All)",ISNUMBER(SEARCH(Contacts!$G$3,$V17))),OR(Contacts!$I$3="(All)",$X17=Contacts!$I$3),OR(Contacts!$K$3="",ISNUMBER(SEARCH(Contacts!$K$3,$B17&" "&$C17&" "&$D17&" "&$S17)))),1,0)) -> 1 | AA17: =IF($Z17=1,COUNTIFS(c_Pass,1,c_Sort,"<="&$Y17),"") -> 16 | AB17: =IF(OR($G17<>"Yes",NOT(ISNUMBER($H17))),"",COUNTIFS(c_Met,"Yes",c_Date,"<"&$H17)+COUNTIFS($G$2:$G17,"Yes",$H$2:$H17,$H17))
A18: =IF($B18="","",COUNTA($B$2:$B18)) -> 17 | B18: Norman Ngai | C18: normanngai@fapl.sg | D18: Financial Alliance | E18: Adviser | F18: Meeting List + ILP Data | G18: Yes | H18: 46043 | I18: 1 | J18: No | K18: 5000000 | N18: No Reply | O18: Declined | P18: Not Invited | Q18: Not Invited | R18: Not Invited | T18: =IF($B18="","",COUNTA($N18:$R18)-COUNTIF($N18:$R18,"Not Invited")) -> 2 | U18: =IF($B18="","",COUNTIF($N18:$R18,"Attended")) -> 0 | V18: =IF($B18="","",_xlfn.TEXTJOIN(", ",TRUE(),IF($N18="Attended",Setup!$D$15,""),IF($O18="Attended",Setup!$D$16,""),IF($P18="Attended",Setup!$D$17,""),IF($Q18="Attended",Setup!$D$18,""),IF($R18="Attended",Setup!$D$19,""))) | W18: =IF(OR($B18="",NOT(ISNUMBER($H18))),"",TODAY()-$H18) -> 198 | X18: =IF($B18="","",IF($U18>0,"Event attendee",IF($G18="Yes","Met (no event)",IF($T18>0,"Invited only",IF(OR($L18="Yes",$M18="Yes"),"Contacted only","Not yet contacted"))))) -> Met (no event) | Y18: =IF($B18="","",COUNTIF(c_Firm,"<"&$D18)+COUNTIFS(c_Firm,$D18,c_Name,"<"&$B18)+COUNTIFS($D$2:$D18,$D18,$B$2:$B18,$B18)) -> 17 | Z18: =IF($B18="","",IF(AND(OR(Contacts!$C$3="(All)",$D18=Contacts!$C$3),OR(Contacts!$E$3="(All)",$G18=Contacts!$E$3),OR(Contacts!$G$3="(All)",ISNUMBER(SEARCH(Contacts!$G$3,$V18))),OR(Contacts!$I$3="(All)",$X18=Contacts!$I$3),OR(Contacts!$K$3="",ISNUMBER(SEARCH(Contacts!$K$3,$B18&" "&$C18&" "&$D18&" "&$S18)))),1,0)) -> 1 | AA18: =IF($Z18=1,COUNTIFS(c_Pass,1,c_Sort,"<="&$Y18),"") -> 17 | AB18: =IF(OR($G18<>"Yes",NOT(ISNUMBER($H18))),"",COUNTIFS(c_Met,"Yes",c_Date,"<"&$H18)+COUNTIFS($G$2:$G18,"Yes",$H$2:$H18,$H18)) -> 41
A19: =IF($B19="","",COUNTA($B$2:$B19)) -> 18 | B19: Paul Chiam | C19: paulchiam@fapl.sg | D19: Financial Alliance | E19: Adviser | F19: Meeting List | G19: No | I19: 0 | J19: No | N19: Not Invited | O19: Attended | P19: Not Invited | Q19: Not Invited | R19: Not Invited | T19: =IF($B19="","",COUNTA($N19:$R19)-COUNTIF($N19:$R19,"Not Invited")) -> 1 | U19: =IF($B19="","",COUNTIF($N19:$R19,"Attended")) -> 1 | V19: =IF($B19="","",_xlfn.TEXTJOIN(", ",TRUE(),IF($N19="Attended",Setup!$D$15,""),IF($O19="Attended",Setup!$D$16,""),IF($P19="Attended",Setup!$D$17,""),IF($Q19="Attended",Setup!$D$18,""),IF($R19="Attended",Setup!$D$19,""))) -> May-26 Symposium | W19: =IF(OR($B19="",NOT(ISNUMBER($H19))),"",TODAY()-$H19) | X19: =IF($B19="","",IF($U19>0,"Event attendee",IF($G19="Yes","Met (no event)",IF($T19>0,"Invited only",IF(OR($L19="Yes",$M19="Yes"),"Contacted only","Not yet contacted"))))) -> Event attendee | Y19: =IF($B19="","",COUNTIF(c_Firm,"<"&$D19)+COUNTIFS(c_Firm,$D19,c_Name,"<"&$B19)+COUNTIFS($D$2:$D19,$D19,$B$2:$B19,$B19)) -> 18 | Z19: =IF($B19="","",IF(AND(OR(Contacts!$C$3="(All)",$D19=Contacts!$C$3),OR(Contacts!$E$3="(All)",$G19=Contacts!$E$3),OR(Contacts!$G$3="(All)",ISNUMBER(SEARCH(Contacts!$G$3,$V19))),OR(Contacts!$I$3="(All)",$X19=Contacts!$I$3),OR(Contacts!$K$3="",ISNUMBER(SEARCH(Contacts!$K$3,$B19&" "&$C19&" "&$D19&" "&$S19)))),1,0)) -> 1 | AA19: =IF($Z19=1,COUNTIFS(c_Pass,1,c_Sort,"<="&$Y19),"") -> 18 | AB19: =IF(OR($G19<>"Yes",NOT(ISNUMBER($H19))),"",COUNTIFS(c_Met,"Yes",c_Date,"<"&$H19)+COUNTIFS($G$2:$G19,"Yes",$H$2:$H19,$H19))
